Workbook

Sheet 1 MNE Group Information
B2: 1 MNE Group Information
A3: please indicate
A4: GIR401 – Ultimate Parent Entity | B4: 1.1 Identification of the Filing Constituent Entity
A5: GIR402 – Designated Filing Entity | B5: 1. UPE is the Filing Constituent Entity | C5: 2. Name of the Filing Constituent Entity | D5: 3. Tax identification number | E5: 4. Role | F5: 5. Jurisdiction where the Filing CE is located | G5: 6. Recipient Jurisdictions for Exchange of Information (if relevant)
A6: GIR403 – Designated Local Entity | B6: yes | C6: Nord Stream AG | D6: CHE-112.660.698 | E6: GIR401 – Ultimate Parent Entity | F6: Switzerland | G6: 0
A7: GIR404 – Constituent Entity | B7: FilingCE | C7: Name | D7: TIN | E7: Role
A8: GIR405 – Other
B9: 1.2 MNE Group General Information
B11: 1.2.1 MNE Group and Reporting Fiscal Year
B12: 1. Name of the MNE Group | C12: 2. Start date of the Reporting Fiscal Year | D12: 3. End date of the Reporting Fiscal Year | E12: 4. Amended Return
A13: please indicate | B13: Nord Stream | C13: 1. January 2024 | D13: 31. December 2024 | E13: no
A14: GIR501– subparagraph a | B14: NameMNE | C14: Start | D14: End
A15: GIR502 – subparagraph b
A16: GIR503 – subparagraph c | B16: 1.2.2 MNE General accounting information | E16: Consolidated Financial Statements means: Subparagraph (a) the financial statements prepared by an Entity in accordance with an Acceptable Financial Accounting Standard, in which the assets, liabilities, income, expenses and cash flows of that Entity and the Entities in which it has a Controlling Interest are presented as those of a single economic unit; Subparagraph (b) where an Entity meets the definition of a Group under Article 1.2.3, the financial statements of the Entity that are prepared in accordance with an Acceptable Financial Accounting Standard; Subparagraph (c) where the Ultimate Parent Entity has financial statements described in paragraph (a) or (b) that are not prepared in accordance with an Acceptable Financial Accounting Standard, the financial statements are those that have been prepared subject to adjustments to prevent any Material Competitive Distortions; and Subparagraph (d) where the Ultimate Parent Entity does not prepare financial statements described in the paragraphs above, the Consolidated Financial Statements of the Ultimate Parent Entity are those that would have been prepared if such Entity were required to prepare such statements in accordance with an Authorised Financial Accounting Standard that is either an Acceptable Financial Accounting Standard or another financial accounting standard that is adjusted to prevent any Material Competitive Distortions.
A17: GIR504 – subparagraph d | B17: 1. Consolidated Financial Statements of the UPE (type) | C17: 2. Financial Accounting standard used for the CFS of the UPE | D17: 3. Presentation currency used for the CFS of the UPE (ISO code)
B18: GIR501– subparagraph a | C18: IFRS | D18: USD
C19: FAS | D19: Currency
B21: 1.3 Corporate Structure
A23: please indicate | B23: 1.3.1 Ultimate Parent Entity
A24: GIR201 – QIIR applicable to Low-Taxed Constituent Entities located in other jurisdictions only | B24: 1. UPE Jurisdiction | C24: Switzerland
A25: GIR202 – QIIR applicable to both Low-Taxed Constituent Entities located in other jurisdictions and in the jurisdiction of the Parent Entity | B25: 2. Applicable rules? | C25: GIR202 – QIIR applicable to both Low-Taxed Constituent Entities located in other jurisdictions and in the jurisdiction of the Parent Entity | D25: Rules
A26: GIR203 – QUTPR | B26: 3. Name of the UPE | C26: Nord Stream AG | D26: UPE
A27: GIR204 – QDMTT | B27: 4. TIN of the UPE | C27: CHE-112.660.698 | D27: TIN
A28: GIR205 – Not applicable | B28: 5. TIN of the UPE in the Filing Jurisdiction (if different, and if any) | C28: not applicable
B29: 6. Status for GloBE purposes | C29: GIR301 – Constituent Entity | D29: GlobeStatus
B30: 7. If the UPE is an Excluded Entity - Type | C30: not applicable | D30: ExcludedUPEStatus
B31: 8. Art. 10.3.5 Jurisdiction (if any) | C31: not applicable | D31: Art10.3.5
B33: 1.3.2 Group Entities (other than the UPE) and members of JV Groups
B34: 1.3.2.1 Constituent Entities and members of JV Groups
B35: Changes | C35: 1. Changes from previous Reporting Fiscal Year? | D35: no
B36: Jurisdiction
B37: 2. Jurisdiction | C37: Switzerland | D37: Germany | E37: Russia | F37: X5 | G37: X5 | H37: X5 | I37: X5
B38: 3. Applicable rules? | C38: GIR202 – QIIR applicable to both Low-Taxed Constituent Entities located in other jurisdictions and in the jurisdiction of the Parent Entity | D38: GIR202 – QIIR applicable to both Low-Taxed Constituent Entities located in other jurisdictions and in the jurisdiction of the Parent Entity | E38: GIR205 – Not applicable | F38: GIR205 – Not applicable | G38: GIR205 – Not applicable | H38: GIR205 – Not applicable | I38: GIR205 – Not applicable
B39: Identification of the Constituent Entity, JV or JV Subsidiary
B40: 4. Name of Constituent Entity, JV or JV Subsidiary | C40: Nord Stream AG | D40: Nord Stream AG (PE Germany) | E40: Nord Stream AG (PE Russia) | F40: Nord Stream AG (Stateless Permanent Establishment Germany) | G40: Nord Stream AG (Stateless Permanent Establishment Denmark) | H40: Nord Stream AG (Stateless Permanent Establishment Sweden) | I40: Nord Stream AG (Stateless Permanent Establishment Finland)
B41: 5. TIN | C41: CHE-112.660.698 | F41: Stateless | G41: Stateless | H41: Stateless | I41: Stateless
B42: 6. TIN for filing jurisdiction (if any)
B43: 7. Status for GloBE purposes | C43: GIR301 – Constituent Entity | D43: GIR305 – Permanent Establishment | E43: GIR305 – Permanent Establishment | F43: GIR305 – Permanent Establishment | G43: GIR305 – Permanent Establishment | H43: GIR305 – Permanent Establishment | I43: GIR305 – Permanent Establishment
B44: Ownership structure of the Constituent Entity, JV or JV Subsidiary. For each entity holding Ownership interests in the Constituent Entity, JV or JV Subsidiary:
B45: 8. Type | C45: GIR801 – UPE | D45: GIR802 – Constituent Entities | E45: GIR802 – Constituent Entities | F45: GIR802 – Constituent Entities | G45: GIR802 – Constituent Entities | H45: GIR802 – Constituent Entities | I45: GIR802 – Constituent Entities
...

Sheet 2 Safe Harbours CH
B2: 2. Jurisdictional safe harbours and exclusions – Jurisdictional schedules
B3: The Filing Constituent Entity shall complete Section 2 on a jurisdictional basis, for each jurisdiction where exceptions to the GloBE computation apply.
B5: 2.1. Characteristics of the jurisdiction
B6: 1. Name of the jurisdiction | C6: Switzerland
B7: 2. Type of subgroup (if any) | C7: not applicable
B8: 3. Identification of subgroup (if any) | C8: not applicable
B9: 4. Jurisdiction with taxing rights | C9: =+C6 -> Switzerland
A10: please indicate yes or no | B10: 5. Existence of reportable differences (Yes/No) | C10: no
A11: yes
A12: no | B12: 2.2. Jurisdictional exceptions applicable in respect of this jurisdiction (Top-up Tax reduced to zero)
B14: 2.2.1. Safe harbour jurisdiction election
B15: 2.2.1.1 Safe harbour election
A16: please indicate | B16: Name of the jurisdiction | C16: =+C6 -> Switzerland
A17: Permanent safe harbours | B17: 1. Safe Harbour elected | C17: GIR1202 – QDMTT safe harbour
A18: Transitional safe harbours
A19: not applicable | B19: 2.2.1.2 Permanent safe harbours
B20: (a) Simplified Calculation for Non-material Constituent Entities
B21: 1. Total Revenue of all NMCEs in the jurisdiction
B22: =+B16 -> Name of the jurisdiction | C22: =+C16 -> Switzerland
B23: a. Reporting Fiscal Year
B24: b. 1st preceding Fiscal Year (if applicable)
B25: c. 2nd preceding Fiscal Year (if applicable)
B26: d. Average of the three Fiscal Years (ifapplicable)
B27: 2. Aggregate Simplified Tax of all NMCEs in the jurisdiction
B28: =+B22 -> Name of the jurisdiction | C28: =+C22 -> Switzerland
B29: a. Reporting Fiscal Year
B30: b. 1st preceding Fiscal Year (if applicable)
B31: c. 2nd preceding Fiscal Year (if applicable)
B32: d. Average of the three Fiscal Years (ifapplicable)
B34: 2.2.1.3 Transitional safe harbours
B35: (a) Transitional CbCR safe harbour
B36: =+B22 -> Name of the jurisdiction | C36: =+C28 -> Switzerland
B37: 1. Total Revenue | C37: 34
B38: 2. Profit (Loss) before Income Tax | C38: 234
B39: 3. Simplified Covered Taxes | C39: 4332
B41: (b) Transitional UTPR safe harbour
B42: 1. Corporate income tax rate
B44: 2.2.2. Election for de minimis exclusion
B45: Election to apply the de minimis exclusion for the Reporting Fiscal Year | C45: no
B46: Simplified Calculations for Non-material Constituent Entities – Constituent Entities that are not NMCEs | C46: no
...

Sheet 2 Safe Harbours DE
B2: 2. Jurisdictional safe harbours and exclusions – Jurisdictional schedules
B3: The Filing Constituent Entity shall complete Section 2 on a jurisdictional basis, for each jurisdiction where exceptions to the GloBE computation apply.
B5: 2.1. Characteristics of the jurisdiction
B6: 1. Name of the jurisdiction | C6: Germany
B7: 2. Type of subgroup (if any) | C7: not applicable
B8: 3. Identification of subgroup (if any) | C8: not applicable
B9: 4. Jurisdiction with taxing rights | C9: =+C6 -> Germany
A10: please indicate yes or no | B10: 5. Existence of reportable differences (Yes/No) | C10: no
A11: yes
A12: no | B12: 2.2. Jurisdictional exceptions applicable in respect of this jurisdiction (Top-up Tax reduced to zero)
B14: 2.2.1. Safe harbour jurisdiction election
B15: 2.2.1.1 Safe harbour election
A16: please indicate | B16: Name of the jurisdiction | C16: =+C6 -> Germany
A17: Permanent safe harbours | B17: 1. Safe Harbour elected | C17: GIR1202 – QDMTT safe harbour
A18: Transitional safe harbours
A19: not applicable | B19: 2.2.1.2 Permanent safe harbours
B20: (a) Simplified Calculation for Non-material Constituent Entities
B21: 1. Total Revenue of all NMCEs in the jurisdiction
B22: =+B16 -> Name of the jurisdiction | C22: =+C16 -> Germany
B23: a. Reporting Fiscal Year
B24: b. 1st preceding Fiscal Year (if applicable)
B25: c. 2nd preceding Fiscal Year (if applicable)
B26: d. Average of the three Fiscal Years (ifapplicable)
B27: 2. Aggregate Simplified Tax of all NMCEs in the jurisdiction
B28: =+B22 -> Name of the jurisdiction | C28: =+C22 -> Germany
B29: a. Reporting Fiscal Year
B30: b. 1st preceding Fiscal Year (if applicable)
B31: c. 2nd preceding Fiscal Year (if applicable)
B32: d. Average of the three Fiscal Years (ifapplicable)
B34: 2.2.1.3 Transitional safe harbours
B35: (a) Transitional CbCR safe harbour
B36: =+B22 -> Name of the jurisdiction | C36: =+C28 -> Germany
B37: 1. Total Revenue | C37: 234554
B38: 2. Profit (Loss) before Income Tax | C38: 86875
B39: 3. Simplified Covered Taxes | C39: 4543
B41: (b) Transitional UTPR safe harbour
B42: 1. Corporate income tax rate
B44: 2.2.2. Election for de minimis exclusion
B45: Election to apply the de minimis exclusion for the Reporting Fiscal Year | C45: no
B46: Simplified Calculations for Non-material Constituent Entities – Constituent Entities that are not NMCEs | C46: no
...

Sheet 2 Safe Harbours RU
B2: 2. Jurisdictional safe harbours and exclusions – Jurisdictional schedules
B3: The Filing Constituent Entity shall complete Section 2 on a jurisdictional basis, for each jurisdiction where exceptions to the GloBE computation apply.
B5: 2.1. Characteristics of the jurisdiction
B6: 1. Name of the jurisdiction | C6: Russia
B7: 2. Type of subgroup (if any) | C7: not applicable
B8: 3. Identification of subgroup (if any) | C8: not applicable
B9: 4. Jurisdiction with taxing rights | C9: =+C6 -> Russia
A10: please indicate yes or no | B10: 5. Existence of reportable differences (Yes/No) | C10: no
A11: yes
A12: no | B12: 2.2. Jurisdictional exceptions applicable in respect of this jurisdiction (Top-up Tax reduced to zero)
B14: 2.2.1. Safe harbour jurisdiction election
B15: 2.2.1.1 Safe harbour election
A16: please indicate | B16: Name of the jurisdiction | C16: =+C6 -> Russia
A17: Permanent safe harbours | B17: 1. Safe Harbour elected | C17: not applicable
A18: Transitional safe harbours
A19: not applicable | B19: 2.2.1.2 Permanent safe harbours
B20: (a) Simplified Calculation for Non-material Constituent Entities
B21: 1. Total Revenue of all NMCEs in the jurisdiction
B22: =+B16 -> Name of the jurisdiction | C22: =+C16 -> Russia
B23: a. Reporting Fiscal Year
B24: b. 1st preceding Fiscal Year (if applicable)
B25: c. 2nd preceding Fiscal Year (if applicable)
B26: d. Average of the three Fiscal Years (ifapplicable)
B27: 2. Aggregate Simplified Tax of all NMCEs in the jurisdiction
B28: =+B22 -> Name of the jurisdiction | C28: =+C22 -> Russia
B29: a. Reporting Fiscal Year
B30: b. 1st preceding Fiscal Year (if applicable)
B31: c. 2nd preceding Fiscal Year (if applicable)
B32: d. Average of the three Fiscal Years (ifapplicable)
B34: 2.2.1.3 Transitional safe harbours
B35: (a) Transitional CbCR safe harbour
B36: =+B22 -> Name of the jurisdiction | C36: =+C28 -> Russia
B37: 1. Total Revenue | C37: 345443
B38: 2. Profit (Loss) before Income Tax | C38: 33433
B39: 3. Simplified Covered Taxes | C39: 344455
B41: (b) Transitional UTPR safe harbour
B42: 1. Corporate income tax rate
B44: 2.2.2. Election for de minimis exclusion
B45: Election to apply the de minimis exclusion for the Reporting Fiscal Year | C45: no
B46: Simplified Calculations for Non-material Constituent Entities – Constituent Entities that are not NMCEs | C46: no
...

Sheet 2 Safe Harbours DK
B2: 2. Jurisdictional safe harbours and exclusions – Jurisdictional schedules
B3: The Filing Constituent Entity shall complete Section 2 on a jurisdictional basis, for each jurisdiction where exceptions to the GloBE computation apply.
B5: 2.1. Characteristics of the jurisdiction
B6: 1. Name of the jurisdiction | C6: Denmark
B7: 2. Type of subgroup (if any) | C7: not applicable
B8: 3. Identification of subgroup (if any) | C8: not applicable
B9: 4. Jurisdiction with taxing rights | C9: =+C6 -> Denmark
A10: please indicate yes or no | B10: 5. Existence of reportable differences (Yes/No) | C10: no
A11: yes
A12: no | B12: 2.2. Jurisdictional exceptions applicable in respect of this jurisdiction (Top-up Tax reduced to zero)
B14: 2.2.1. Safe harbour jurisdiction election
B15: 2.2.1.1 Safe harbour election
A16: please indicate | B16: Name of the jurisdiction | C16: =+C6 -> Denmark
A17: Permanent safe harbours | B17: 1. Safe Harbour elected | C17: GIR1202 – QDMTT safe harbour
A18: Transitional safe harbours
A19: not applicable | B19: 2.2.1.2 Permanent safe harbours
B20: (a) Simplified Calculation for Non-material Constituent Entities
B21: 1. Total Revenue of all NMCEs in the jurisdiction
B22: =+B16 -> Name of the jurisdiction | C22: =+C16 -> Denmark
B23: a. Reporting Fiscal Year
B24: b. 1st preceding Fiscal Year (if applicable)
B25: c. 2nd preceding Fiscal Year (if applicable)
B26: d. Average of the three Fiscal Years (ifapplicable)
B27: 2. Aggregate Simplified Tax of all NMCEs in the jurisdiction
B28: =+B22 -> Name of the jurisdiction | C28: =+C22 -> Denmark
B29: a. Reporting Fiscal Year
B30: b. 1st preceding Fiscal Year (if applicable)
B31: c. 2nd preceding Fiscal Year (if applicable)
B32: d. Average of the three Fiscal Years (ifapplicable)
B34: 2.2.1.3 Transitional safe harbours
B35: (a) Transitional CbCR safe harbour
B36: =+B22 -> Name of the jurisdiction | C36: =+C28 -> Denmark
B37: 1. Total Revenue | C37: 876456
B38: 2. Profit (Loss) before Income Tax | C38: 4576
B39: 3. Simplified Covered Taxes | C39: 123876
B41: (b) Transitional UTPR safe harbour
B42: 1. Corporate income tax rate
B44: 2.2.2. Election for de minimis exclusion
B45: Election to apply the de minimis exclusion for the Reporting Fiscal Year | C45: no
B46: Simplified Calculations for Non-material Constituent Entities – Constituent Entities that are not NMCEs | C46: no
...

Sheet 2 Safe Harbours SE
B2: 2. Jurisdictional safe harbours and exclusions – Jurisdictional schedules
B3: The Filing Constituent Entity shall complete Section 2 on a jurisdictional basis, for each jurisdiction where exceptions to the GloBE computation apply.
B5: 2.1. Characteristics of the jurisdiction
B6: 1. Name of the jurisdiction | C6: Sweden
B7: 2. Type of subgroup (if any) | C7: not applicable
B8: 3. Identification of subgroup (if any) | C8: not applicable
B9: 4. Jurisdiction with taxing rights | C9: =+C6 -> Sweden
A10: please indicate yes or no | B10: 5. Existence of reportable differences (Yes/No) | C10: no
A11: yes
A12: no | B12: 2.2. Jurisdictional exceptions applicable in respect of this jurisdiction (Top-up Tax reduced to zero)
B14: 2.2.1. Safe harbour jurisdiction election
B15: 2.2.1.1 Safe harbour election
A16: please indicate | B16: Name of the jurisdiction | C16: =+C6 -> Sweden
A17: Permanent safe harbours | B17: 1. Safe Harbour elected | C17: GIR1202 – QDMTT safe harbour
A18: Transitional safe harbours
A19: not applicable | B19: 2.2.1.2 Permanent safe harbours
B20: (a) Simplified Calculation for Non-material Constituent Entities
B21: 1. Total Revenue of all NMCEs in the jurisdiction
B22: =+B16 -> Name of the jurisdiction | C22: =+C16 -> Sweden
B23: a. Reporting Fiscal Year
B24: b. 1st preceding Fiscal Year (if applicable)
B25: c. 2nd preceding Fiscal Year (if applicable)
B26: d. Average of the three Fiscal Years (ifapplicable)
B27: 2. Aggregate Simplified Tax of all NMCEs in the jurisdiction
B28: =+B22 -> Name of the jurisdiction | C28: =+C22 -> Sweden
B29: a. Reporting Fiscal Year
B30: b. 1st preceding Fiscal Year (if applicable)
B31: c. 2nd preceding Fiscal Year (if applicable)
B32: d. Average of the three Fiscal Years (ifapplicable)
B34: 2.2.1.3 Transitional safe harbours
B35: (a) Transitional CbCR safe harbour
B36: =+B22 -> Name of the jurisdiction | C36: =+C28 -> Sweden
B37: 1. Total Revenue | C37: 435876
B38: 2. Profit (Loss) before Income Tax | C38: 45789876
B39: 3. Simplified Covered Taxes | C39: 345687
B41: (b) Transitional UTPR safe harbour
B42: 1. Corporate income tax rate
B44: 2.2.2. Election for de minimis exclusion
B45: Election to apply the de minimis exclusion for the Reporting Fiscal Year | C45: no
B46: Simplified Calculations for Non-material Constituent Entities – Constituent Entities that are not NMCEs | C46: no
...

Sheet 2 Safe Harbours FI
B2: 2. Jurisdictional safe harbours and exclusions – Jurisdictional schedules
B3: The Filing Constituent Entity shall complete Section 2 on a jurisdictional basis, for each jurisdiction where exceptions to the GloBE computation apply.
B5: 2.1. Characteristics of the jurisdiction
B6: 1. Name of the jurisdiction | C6: Finland
B7: 2. Type of subgroup (if any) | C7: not applicable
B8: 3. Identification of subgroup (if any) | C8: not applicable
B9: 4. Jurisdiction with taxing rights | C9: =+C6 -> Finland
A10: please indicate yes or no | B10: 5. Existence of reportable differences (Yes/No) | C10: no
A11: yes
A12: no | B12: 2.2. Jurisdictional exceptions applicable in respect of this jurisdiction (Top-up Tax reduced to zero)
B14: 2.2.1. Safe harbour jurisdiction election
B15: 2.2.1.1 Safe harbour election
A16: please indicate | B16: Name of the jurisdiction | C16: =+C6 -> Finland
A17: Permanent safe harbours | B17: 1. Safe Harbour elected | C17: GIR1202 – QDMTT safe harbour
A18: Transitional safe harbours
A19: not applicable | B19: 2.2.1.2 Permanent safe harbours
B20: (a) Simplified Calculation for Non-material Constituent Entities
B21: 1. Total Revenue of all NMCEs in the jurisdiction
B22: =+B16 -> Name of the jurisdiction | C22: =+C16 -> Finland
B23: a. Reporting Fiscal Year
B24: b. 1st preceding Fiscal Year (if applicable)
B25: c. 2nd preceding Fiscal Year (if applicable)
B26: d. Average of the three Fiscal Years (ifapplicable)
B27: 2. Aggregate Simplified Tax of all NMCEs in the jurisdiction
B28: =+B22 -> Name of the jurisdiction | C28: =+C22 -> Finland
B29: a. Reporting Fiscal Year
B30: b. 1st preceding Fiscal Year (if applicable)
B31: c. 2nd preceding Fiscal Year (if applicable)
B32: d. Average of the three Fiscal Years (ifapplicable)
B34: 2.2.1.3 Transitional safe harbours
B35: (a) Transitional CbCR safe harbour
B36: =+B22 -> Name of the jurisdiction | C36: =+C28 -> Finland
B37: 1. Total Revenue | C37: 3456876
B38: 2. Profit (Loss) before Income Tax | C38: 45678765
B39: 3. Simplified Covered Taxes | C39: 465
B41: (b) Transitional UTPR safe harbour
B42: 1. Corporate income tax rate
B44: 2.2.2. Election for de minimis exclusion
B45: Election to apply the de minimis exclusion for the Reporting Fiscal Year | C45: no
B46: Simplified Calculations for Non-material Constituent Entities – Constituent Entities that are not NMCEs | C46: no
...

Sheet 3 GloBE Computations CH
D2: 3 GloBE Computations
D3: The Filing Constituent Entity shall complete Section 3 on a jurisdictional basis, for each jurisdiction (or subgroup, where relevant) where exceptions to the GloBE computation do not apply
D5: Please make sure that only the yellow marked cells are populated. Don't include or delete any other cell, row or column! | E5: To be populated
D6: References to GloBE Information Return (Pillar Two) XML Schema User Guide for Tax Administrations are in light clue | E6: XML references
D7: Further explanations are in light green | E7: Further explanations
D9: 3.1 Characteristics of the jurisdiction (Information purpose only)
D10: 1. Name of the jurisdiction | E10: Switzerland
D11: 2. Type of subgroup (if any) - mention "n/a" if no subgroup exists | E11: n/a
D12: 3. Identification of subgroup (if any) for the ETR and Top-up Tax computation - mention "n/a" if no subgroup exists | E12: n/a
D13: 4. Jurisdictions with taxing rights | E13: Switzerland
D14: 5. ETR | E14: =+E36 -> 0.015049035
D15: 6. Adjusted Covered Taxes | E15: =+E35 -> 3582188
D16: 7. Net GloBE Income or Loss | E16: =+E33 -> 238034398
D17: 8. Substance-based Income Exclusion | E17: =+E437 -> 341400
D18: 9. Additional Current Top-up Tax | E18: =+E475 -> 0
D19: 10.Top-up Tax amount under domestic legislation | E19: =+E425 -> 32076899
D20: 11. Elections
D21: 12. Aggregate current tax expense with respect to Covered Taxes after allocations in Article 4.3 | E21: =+E73 -> 3457864
D22: 13. Qualified Refundable Tax Credits or Marketable Transferable Tax Credits (tax expense) | E22: =+E78 -> 0
D23: 14. Other tax credits (tax expense) | E23: =+E81 -> 0
D24: 15. Deferred tax expense amount | E24: =+F123 -> 124324
D25: 16. Qualified Refundable Tax Credits or Marketable Transferable Tax Credits (income) | E25: =+E55 -> 0
D26: 17. Excess Negative Tax Expense Carry Forward | E26: =E93 -> 0
D27: 18. Transition Rules
D30: 3.2 ETR computation | E30: applicable
D31: 3.2.1 ETR | E31: applicable | F31: OverallComputation
D32: a. Financial Accounting Net Income or Loss | E32: =+M233 -> 234576534 | F32: FANIL | G32: Note 3.2.1.a
D33: b. Net GloBE Income or Loss [A] | E33: =+E68 -> 238034398 | F33: NetGlobeIncome | G33: Note 3.2.1.b
D34: c. Income tax expense | E34: =+E42 -> 3457864 | F34: IncomeTaxExpense | G34: Note 3.2.1.c
D35: d. Adjusted Covered Taxes [B] | E35: =+M311 -> 3582188 | F35: AdjustedCoveredTax | G35: Note 3.2.1.d
D36: e. ETR [C]=[B]/[A] | E36: =+E35/E33 -> 0.015049035 | F36: ETRRate | G36: Note 3.2.1.e
D39: 3.2.1.1 Computation of GloBE Income (Loss) of the Jurisdiction
D40: 1. Aggregate FANIL amount after allocations in Articles 3.4 and 3.5 (All CEs in the jurisdiction) | E40: =+M233 -> 234576534 | F40: AdjustedFANIL
D41: 2. Adjustments | E41: Net amount | F41: Adjustments
D42: (a) Net Taxes Expense - Article 3.2.1 (a) | E42: =+M235 -> 3457864 | F42: GIR2001 | G42: Note 3.2.1.1.2a
D43: (b) Excluded Dividends – Article 3.2.1 (b) | E43: =+M236 -> 0 | F43: GIR2002 | G43: Note 3.2.1.1.2b
D44: (c) Excluded Equity Gain or Loss – Article 3.2.1 (c) | E44: =+M237 -> 0 | F44: GIR2003 | G44: Note 3.2.1.1.2c
D45: (d) Included Revaluation Method Gain or Loss – Article 3.2.1 (d) | E45: =+M238 -> 0 | F45: GIR2004 | G45: Note 3.2.1.1.2d
D46: (e) Gain or loss from disposition of assets and liabilities excluded under Article 6.3 – Article 3.2.1 (e) | E46: =+M239 -> 0 | F46: GIR2005 | G46: Note 3.2.1.1.2e
D47: (f) Asymmetric Foreign Currency Gains or Losses – Article 3.2.1 (f) | E47: =+M240 -> 0 | F47: GIR2006 | G47: Note 3.2.1.1.2f
...

Sheet 3 GloBE Computations DE
D2: 3 GloBE Computations
D3: The Filing Constituent Entity shall complete Section 3 on a jurisdictional basis, for each jurisdiction (or subgroup, where relevant) where exceptions to the GloBE computation do not apply
D5: Please make sure that only the yellow marked cells are populated. Don't include or delete any other cell, row or column! | E5: To be populated
D6: References to GloBE Information Return (Pillar Two) XML Schema User Guide for Tax Administrations are in light clue | E6: XML references
D7: Further explanations are in light green | E7: Further explanations
D9: 3.1 Characteristics of the jurisdiction (Information purpose only)
D10: 1. Name of the jurisdiction | E10: Germany
D11: 2. Type of subgroup (if any) - mention "n/a" if no subgroup exists | E11: n/a
D12: 3. Identification of subgroup (if any) for the ETR and Top-up Tax computation - mention "n/a" if no subgroup exists | E12: n/a
D13: 4. Jurisdictions with taxing rights | E13: Germany
D14: 5. ETR | E14: =+E36 -> 0.014526739
D15: 6. Adjusted Covered Taxes | E15: =+E35 -> 3803650
D16: 7. Net GloBE Income or Loss | E16: =+E33 -> 261837837
D17: 8. Substance-based Income Exclusion | E17: =+E437 -> 682800
D18: 9. Additional Current Top-up Tax | E18: =+E475 -> 0
D19: 10.Top-up Tax amount under domestic legislation | E19: =+E425 -> 35379524
D20: 11. Elections
D21: 12. Aggregate current tax expense with respect to Covered Taxes after allocations in Article 4.3 | E21: =+E73 -> 3803650
D22: 13. Qualified Refundable Tax Credits or Marketable Transferable Tax Credits (tax expense) | E22: =+E78 -> 0
D23: 14. Other tax credits (tax expense) | E23: =+E81 -> 0
D24: 15. Deferred tax expense amount | E24: =+F123 -> 125558
D25: 16. Qualified Refundable Tax Credits or Marketable Transferable Tax Credits (income) | E25: =+E55 -> 0
D26: 17. Excess Negative Tax Expense Carry Forward | E26: =E93 -> 0
D27: 18. Transition Rules
D30: 3.2 ETR computation | E30: applicable
D31: 3.2.1 ETR | E31: applicable | F31: OverallComputation
D32: a. Financial Accounting Net Income or Loss | E32: =+M233 -> 258034187 | F32: FANIL | G32: Note 3.2.1.a
D33: b. Net GloBE Income or Loss [A] | E33: =+E68 -> 261837837 | F33: NetGlobeIncome | G33: Note 3.2.1.b
D34: c. Income tax expense | E34: =+E42 -> 3803650 | F34: IncomeTaxExpense | G34: Note 3.2.1.c
D35: d. Adjusted Covered Taxes [B] | E35: =+M311 -> 3803650 | F35: AdjustedCoveredTax | G35: Note 3.2.1.d
D36: e. ETR [C]=[B]/[A] | E36: =+E35/E33 -> 0.014526739 | F36: ETRRate | G36: Note 3.2.1.e
D39: 3.2.1.1 Computation of GloBE Income (Loss) of the Jurisdiction
D40: 1. Aggregate FANIL amount after allocations in Articles 3.4 and 3.5 (All CEs in the jurisdiction) | E40: =+M233 -> 258034187 | F40: AdjustedFANIL
D41: 2. Adjustments | E41: Net amount | F41: Adjustments
D42: (a) Net Taxes Expense - Article 3.2.1 (a) | E42: =+M235 -> 3803650 | F42: GIR2001 | G42: Note 3.2.1.1.2a
D43: (b) Excluded Dividends – Article 3.2.1 (b) | E43: =+M236 -> 0 | F43: GIR2002 | G43: Note 3.2.1.1.2b
D44: (c) Excluded Equity Gain or Loss – Article 3.2.1 (c) | E44: =+M237 -> 0 | F44: GIR2003 | G44: Note 3.2.1.1.2c
D45: (d) Included Revaluation Method Gain or Loss – Article 3.2.1 (d) | E45: =+M238 -> 0 | F45: GIR2004 | G45: Note 3.2.1.1.2d
D46: (e) Gain or loss from disposition of assets and liabilities excluded under Article 6.3 – Article 3.2.1 (e) | E46: =+M239 -> 0 | F46: GIR2005 | G46: Note 3.2.1.1.2e
D47: (f) Asymmetric Foreign Currency Gains or Losses – Article 3.2.1 (f) | E47: =+M240 -> 0 | F47: GIR2006 | G47: Note 3.2.1.1.2f
...

Sheet 3 GloBE Computations RU
D2: 3 GloBE Computations
D3: The Filing Constituent Entity shall complete Section 3 on a jurisdictional basis, for each jurisdiction (or subgroup, where relevant) where exceptions to the GloBE computation do not apply
D5: Please make sure that only the yellow marked cells are populated. Don't include or delete any other cell, row or column! | E5: To be populated
D6: References to GloBE Information Return (Pillar Two) XML Schema User Guide for Tax Administrations are in light clue | E6: XML references
D7: Further explanations are in light green | E7: Further explanations
D9: 3.1 Characteristics of the jurisdiction (Information purpose only)
D10: 1. Name of the jurisdiction | E10: Russia
D11: 2. Type of subgroup (if any) - mention "n/a" if no subgroup exists | E11: n/a
D12: 3. Identification of subgroup (if any) for the ETR and Top-up Tax computation - mention "n/a" if no subgroup exists | E12: n/a
D13: 4. Jurisdictions with taxing rights | E13: Switzerland
D14: 5. ETR | E14: =+E36 -> 0.49998934
D15: 6. Adjusted Covered Taxes | E15: =+E35 -> 23456
D16: 7. Net GloBE Income or Loss | E16: =+E33 -> 46913
D17: 8. Substance-based Income Exclusion | E17: =+E437 -> 341400
D18: 9. Additional Current Top-up Tax | E18: =+E475 -> 0
D19: 10.Top-up Tax amount under domestic legislation | E19: =+E425 -> 0
D20: 11. Elections
D21: 12. Aggregate current tax expense with respect to Covered Taxes after allocations in Article 4.3 | E21: =+E73 -> 23456
D22: 13. Qualified Refundable Tax Credits or Marketable Transferable Tax Credits (tax expense) | E22: =+E78 -> 0
D23: 14. Other tax credits (tax expense) | E23: =+E81 -> 0
D24: 15. Deferred tax expense amount | E24: =+F123 -> 65443
D25: 16. Qualified Refundable Tax Credits or Marketable Transferable Tax Credits (income) | E25: =+E55 -> 0
D26: 17. Excess Negative Tax Expense Carry Forward | E26: =E93 -> 0
D27: 18. Transition Rules
D30: 3.2 ETR computation | E30: applicable
D31: 3.2.1 ETR | E31: applicable | F31: OverallComputation
D32: a. Financial Accounting Net Income or Loss | E32: =+M233 -> 23457 | F32: FANIL | G32: Note 3.2.1.a
D33: b. Net GloBE Income or Loss [A] | E33: =+E68 -> 46913 | F33: NetGlobeIncome | G33: Note 3.2.1.b
D34: c. Income tax expense | E34: =+E42 -> 23456 | F34: IncomeTaxExpense | G34: Note 3.2.1.c
D35: d. Adjusted Covered Taxes [B] | E35: =+M311 -> 23456 | F35: AdjustedCoveredTax | G35: Note 3.2.1.d
D36: e. ETR [C]=[B]/[A] | E36: =+E35/E33 -> 0.49998934 | F36: ETRRate | G36: Note 3.2.1.e
D39: 3.2.1.1 Computation of GloBE Income (Loss) of the Jurisdiction
D40: 1. Aggregate FANIL amount after allocations in Articles 3.4 and 3.5 (All CEs in the jurisdiction) | E40: =+M233 -> 23457 | F40: AdjustedFANIL
D41: 2. Adjustments | E41: Net amount | F41: Adjustments
D42: (a) Net Taxes Expense - Article 3.2.1 (a) | E42: =+M235 -> 23456 | F42: GIR2001 | G42: Note 3.2.1.1.2a
D43: (b) Excluded Dividends – Article 3.2.1 (b) | E43: =+M236 -> 0 | F43: GIR2002 | G43: Note 3.2.1.1.2b
D44: (c) Excluded Equity Gain or Loss – Article 3.2.1 (c) | E44: =+M237 -> 0 | F44: GIR2003 | G44: Note 3.2.1.1.2c
D45: (d) Included Revaluation Method Gain or Loss – Article 3.2.1 (d) | E45: =+M238 -> 0 | F45: GIR2004 | G45: Note 3.2.1.1.2d
D46: (e) Gain or loss from disposition of assets and liabilities excluded under Article 6.3 – Article 3.2.1 (e) | E46: =+M239 -> 0 | F46: GIR2005 | G46: Note 3.2.1.1.2e
D47: (f) Asymmetric Foreign Currency Gains or Losses – Article 3.2.1 (f) | E47: =+M240 -> 0 | F47: GIR2006 | G47: Note 3.2.1.1.2f
...

Sheet 3 GloBE Computations DK
D2: 3 GloBE Computations
D3: The Filing Constituent Entity shall complete Section 3 on a jurisdictional basis, for each jurisdiction (or subgroup, where relevant) where exceptions to the GloBE computation do not apply
D5: Please make sure that only the yellow marked cells are populated. Don't include or delete any other cell, row or column! | E5: To be populated
D6: References to GloBE Information Return (Pillar Two) XML Schema User Guide for Tax Administrations are in light clue | E6: XML references
D7: Further explanations are in light green | E7: Further explanations
D9: 3.1 Characteristics of the jurisdiction (Information purpose only)
D10: 1. Name of the jurisdiction | E10: Denmark
D11: 2. Type of subgroup (if any) - mention "n/a" if no subgroup exists | E11: n/a
D12: 3. Identification of subgroup (if any) for the ETR and Top-up Tax computation - mention "n/a" if no subgroup exists | E12: n/a
D13: 4. Jurisdictions with taxing rights | E13: Denmark
D14: 5. ETR | E14: =+E36 -> 0.038699763
D15: 6. Adjusted Covered Taxes | E15: =+E35 -> 3456765
D16: 7. Net GloBE Income or Loss | E16: =+E33 -> 89322639
D17: 8. Substance-based Income Exclusion | E17: =+E437 -> 341400
D18: 9. Additional Current Top-up Tax | E18: =+E475 -> 0
D19: 10.Top-up Tax amount under domestic legislation | E19: =+E425 -> 9903632.9
D20: 11. Elections
D21: 12. Aggregate current tax expense with respect to Covered Taxes after allocations in Article 4.3 | E21: =+E73 -> 3456765
D22: 13. Qualified Refundable Tax Credits or Marketable Transferable Tax Credits (tax expense) | E22: =+E78 -> 0
D23: 14. Other tax credits (tax expense) | E23: =+E81 -> 0
D24: 15. Deferred tax expense amount | E24: =+F123 -> 4565
D25: 16. Qualified Refundable Tax Credits or Marketable Transferable Tax Credits (income) | E25: =+E55 -> 0
D26: 17. Excess Negative Tax Expense Carry Forward | E26: =E93 -> 0
D27: 18. Transition Rules
D30: 3.2 ETR computation | E30: applicable
D31: 3.2.1 ETR | E31: applicable | F31: OverallComputation
D32: a. Financial Accounting Net Income or Loss | E32: =+M233 -> 85865874 | F32: FANIL | G32: Note 3.2.1.a
D33: b. Net GloBE Income or Loss [A] | E33: =+E68 -> 89322639 | F33: NetGlobeIncome | G33: Note 3.2.1.b
D34: c. Income tax expense | E34: =+E42 -> 3456765 | F34: IncomeTaxExpense | G34: Note 3.2.1.c
D35: d. Adjusted Covered Taxes [B] | E35: =+M311 -> 3456765 | F35: AdjustedCoveredTax | G35: Note 3.2.1.d
D36: e. ETR [C]=[B]/[A] | E36: =+E35/E33 -> 0.038699763 | F36: ETRRate | G36: Note 3.2.1.e
D39: 3.2.1.1 Computation of GloBE Income (Loss) of the Jurisdiction
D40: 1. Aggregate FANIL amount after allocations in Articles 3.4 and 3.5 (All CEs in the jurisdiction) | E40: =+M233 -> 85865874 | F40: AdjustedFANIL
D41: 2. Adjustments | E41: Net amount | F41: Adjustments
D42: (a) Net Taxes Expense - Article 3.2.1 (a) | E42: =+M235 -> 3456765 | F42: GIR2001 | G42: Note 3.2.1.1.2a
D43: (b) Excluded Dividends – Article 3.2.1 (b) | E43: =+M236 -> 0 | F43: GIR2002 | G43: Note 3.2.1.1.2b
D44: (c) Excluded Equity Gain or Loss – Article 3.2.1 (c) | E44: =+M237 -> 0 | F44: GIR2003 | G44: Note 3.2.1.1.2c
D45: (d) Included Revaluation Method Gain or Loss – Article 3.2.1 (d) | E45: =+M238 -> 0 | F45: GIR2004 | G45: Note 3.2.1.1.2d
D46: (e) Gain or loss from disposition of assets and liabilities excluded under Article 6.3 – Article 3.2.1 (e) | E46: =+M239 -> 0 | F46: GIR2005 | G46: Note 3.2.1.1.2e
D47: (f) Asymmetric Foreign Currency Gains or Losses – Article 3.2.1 (f) | E47: =+M240 -> 0 | F47: GIR2006 | G47: Note 3.2.1.1.2f
...

Sheet 3 GloBE Computations SE
D2: 3 GloBE Computations
D3: The Filing Constituent Entity shall complete Section 3 on a jurisdictional basis, for each jurisdiction (or subgroup, where relevant) where exceptions to the GloBE computation do not apply
D5: Please make sure that only the yellow marked cells are populated. Don't include or delete any other cell, row or column! | E5: To be populated
D6: References to GloBE Information Return (Pillar Two) XML Schema User Guide for Tax Administrations are in light clue | E6: XML references
D7: Further explanations are in light green | E7: Further explanations
D9: 3.1 Characteristics of the jurisdiction (Information purpose only)
D10: 1. Name of the jurisdiction | E10: Sweden
D11: 2. Type of subgroup (if any) - mention "n/a" if no subgroup exists | E11: n/a
D12: 3. Identification of subgroup (if any) for the ETR and Top-up Tax computation - mention "n/a" if no subgroup exists | E12: n/a
D13: 4. Jurisdictions with taxing rights | E13: Sweden
D14: 5. ETR | E14: =+E36 -> 0.70370381
D15: 6. Adjusted Covered Taxes | E15: =+E35 -> 234567
D16: 7. Net GloBE Income or Loss | E16: =+E33 -> 333332
D17: 8. Substance-based Income Exclusion | E17: =+E437 -> 341400
D18: 9. Additional Current Top-up Tax | E18: =+E475 -> 0
D19: 10.Top-up Tax amount under domestic legislation | E19: =+E425 -> 0
D20: 11. Elections
D21: 12. Aggregate current tax expense with respect to Covered Taxes after allocations in Article 4.3 | E21: =+E73 -> 234567
D22: 13. Qualified Refundable Tax Credits or Marketable Transferable Tax Credits (tax expense) | E22: =+E78 -> 0
D23: 14. Other tax credits (tax expense) | E23: =+E81 -> 0
D24: 15. Deferred tax expense amount | E24: =+F123 -> 3456
D25: 16. Qualified Refundable Tax Credits or Marketable Transferable Tax Credits (income) | E25: =+E55 -> 0
D26: 17. Excess Negative Tax Expense Carry Forward | E26: =E93 -> 0
D27: 18. Transition Rules
D30: 3.2 ETR computation | E30: applicable
D31: 3.2.1 ETR | E31: applicable | F31: OverallComputation
D32: a. Financial Accounting Net Income or Loss | E32: =+M233 -> 98765 | F32: FANIL | G32: Note 3.2.1.a
D33: b. Net GloBE Income or Loss [A] | E33: =+E68 -> 333332 | F33: NetGlobeIncome | G33: Note 3.2.1.b
D34: c. Income tax expense | E34: =+E42 -> 234567 | F34: IncomeTaxExpense | G34: Note 3.2.1.c
D35: d. Adjusted Covered Taxes [B] | E35: =+M311 -> 234567 | F35: AdjustedCoveredTax | G35: Note 3.2.1.d
D36: e. ETR [C]=[B]/[A] | E36: =+E35/E33 -> 0.70370381 | F36: ETRRate | G36: Note 3.2.1.e
D39: 3.2.1.1 Computation of GloBE Income (Loss) of the Jurisdiction
D40: 1. Aggregate FANIL amount after allocations in Articles 3.4 and 3.5 (All CEs in the jurisdiction) | E40: =+M233 -> 98765 | F40: AdjustedFANIL
D41: 2. Adjustments | E41: Net amount | F41: Adjustments
D42: (a) Net Taxes Expense - Article 3.2.1 (a) | E42: =+M235 -> 234567 | F42: GIR2001 | G42: Note 3.2.1.1.2a
D43: (b) Excluded Dividends – Article 3.2.1 (b) | E43: =+M236 -> 0 | F43: GIR2002 | G43: Note 3.2.1.1.2b
D44: (c) Excluded Equity Gain or Loss – Article 3.2.1 (c) | E44: =+M237 -> 0 | F44: GIR2003 | G44: Note 3.2.1.1.2c
D45: (d) Included Revaluation Method Gain or Loss – Article 3.2.1 (d) | E45: =+M238 -> 0 | F45: GIR2004 | G45: Note 3.2.1.1.2d
D46: (e) Gain or loss from disposition of assets and liabilities excluded under Article 6.3 – Article 3.2.1 (e) | E46: =+M239 -> 0 | F46: GIR2005 | G46: Note 3.2.1.1.2e
D47: (f) Asymmetric Foreign Currency Gains or Losses – Article 3.2.1 (f) | E47: =+M240 -> 0 | F47: GIR2006 | G47: Note 3.2.1.1.2f
...

Sheet 3 GloBE Computations FI
D2: 3 GloBE Computations
D3: The Filing Constituent Entity shall complete Section 3 on a jurisdictional basis, for each jurisdiction (or subgroup, where relevant) where exceptions to the GloBE computation do not apply
D5: Please make sure that only the yellow marked cells are populated. Don't include or delete any other cell, row or column! | E5: To be populated
D6: References to GloBE Information Return (Pillar Two) XML Schema User Guide for Tax Administrations are in light clue | E6: XML references
D7: Further explanations are in light green | E7: Further explanations
D9: 3.1 Characteristics of the jurisdiction (Information purpose only)
D10: 1. Name of the jurisdiction | E10: Finland
D11: 2. Type of subgroup (if any) - mention "n/a" if no subgroup exists | E11: n/a
D12: 3. Identification of subgroup (if any) for the ETR and Top-up Tax computation - mention "n/a" if no subgroup exists | E12: n/a
D13: 4. Jurisdictions with taxing rights | E13: Finland
D14: 5. ETR | E14: =+E36 -> 0.40442656
D15: 6. Adjusted Covered Taxes | E15: =+E35 -> 234567
D16: 7. Net GloBE Income or Loss | E16: =+E33 -> 579999
D17: 8. Substance-based Income Exclusion | E17: =+E437 -> 341400
D18: 9. Additional Current Top-up Tax | E18: =+E475 -> 0
D19: 10.Top-up Tax amount under domestic legislation | E19: =+E425 -> 0
D20: 11. Elections
D21: 12. Aggregate current tax expense with respect to Covered Taxes after allocations in Article 4.3 | E21: =+E73 -> 234567
D22: 13. Qualified Refundable Tax Credits or Marketable Transferable Tax Credits (tax expense) | E22: =+E78 -> 0
D23: 14. Other tax credits (tax expense) | E23: =+E81 -> 0
D24: 15. Deferred tax expense amount | E24: =+F123 -> 2343
D25: 16. Qualified Refundable Tax Credits or Marketable Transferable Tax Credits (income) | E25: =+E55 -> 0
D26: 17. Excess Negative Tax Expense Carry Forward | E26: =E93 -> 0
D27: 18. Transition Rules
D30: 3.2 ETR computation | E30: applicable
D31: 3.2.1 ETR | E31: applicable | F31: OverallComputation
D32: a. Financial Accounting Net Income or Loss | E32: =+M233 -> 345432 | F32: FANIL | G32: Note 3.2.1.a
D33: b. Net GloBE Income or Loss [A] | E33: =+E68 -> 579999 | F33: NetGlobeIncome | G33: Note 3.2.1.b
D34: c. Income tax expense | E34: =+E42 -> 234567 | F34: IncomeTaxExpense | G34: Note 3.2.1.c
D35: d. Adjusted Covered Taxes [B] | E35: =+M311 -> 234567 | F35: AdjustedCoveredTax | G35: Note 3.2.1.d
D36: e. ETR [C]=[B]/[A] | E36: =+E35/E33 -> 0.40442656 | F36: ETRRate | G36: Note 3.2.1.e
D39: 3.2.1.1 Computation of GloBE Income (Loss) of the Jurisdiction
D40: 1. Aggregate FANIL amount after allocations in Articles 3.4 and 3.5 (All CEs in the jurisdiction) | E40: =+M233 -> 345432 | F40: AdjustedFANIL
D41: 2. Adjustments | E41: Net amount | F41: Adjustments
D42: (a) Net Taxes Expense - Article 3.2.1 (a) | E42: =+M235 -> 234567 | F42: GIR2001 | G42: Note 3.2.1.1.2a
D43: (b) Excluded Dividends – Article 3.2.1 (b) | E43: =+M236 -> 0 | F43: GIR2002 | G43: Note 3.2.1.1.2b
D44: (c) Excluded Equity Gain or Loss – Article 3.2.1 (c) | E44: =+M237 -> 0 | F44: GIR2003 | G44: Note 3.2.1.1.2c
D45: (d) Included Revaluation Method Gain or Loss – Article 3.2.1 (d) | E45: =+M238 -> 0 | F45: GIR2004 | G45: Note 3.2.1.1.2d
D46: (e) Gain or loss from disposition of assets and liabilities excluded under Article 6.3 – Article 3.2.1 (e) | E46: =+M239 -> 0 | F46: GIR2005 | G46: Note 3.2.1.1.2e
D47: (f) Asymmetric Foreign Currency Gains or Losses – Article 3.2.1 (f) | E47: =+M240 -> 0 | F47: GIR2006 | G47: Note 3.2.1.1.2f
...
